=========================
time:2018-02-28 14:04:53,937 
logger:user 
level:ERROR 
file:log.py 
fun:error 
lineno:67 
message:Traceback (most recent call last):
  File "F:\git\myprojecttest\apptest\user.py", line 34, in register
    valdata=1/0
ZeroDivisionError: division by zero

=========================
time:2018-02-28 14:06:58,053 
logger:user 
level:ERROR 
file:log.py 
fun:error 
lineno:66 
message:Traceback (most recent call last):
  File "F:\git\myprojecttest\apptest\user.py", line 34, in register
    valdata = 2 / 0
ZeroDivisionError: division by zero

=========================
time:2018-02-28 16:07:35,684 
logger:user 
level:ERROR 
file:log.py 
fun:error 
lineno:66 
message:Traceback (most recent call last):
  File "F:\git\myprojecttest\apptest\user.py", line 78, in login
    response_data = {"state": 1, "message": "登录成功","data":dict,"money":money}
UnboundLocalError: local variable 'money' referenced before assignment

=========================
time:2018-02-28 16:11:52,103 
logger:user 
level:ERROR 
file:log.py 
fun:error 
lineno:66 
message:Traceback (most recent call last):
  File "F:\git\myprojecttest\apptest\user.py", line 79, in login
    response_data = {"state": 1, "message": "登录成功","data":dict,"money":money}
UnboundLocalError: local variable 'money' referenced before assignment

=========================
time:2018-02-28 16:12:46,546 
logger:user 
level:ERROR 
file:log.py 
fun:error 
lineno:66 
message:Traceback (most recent call last):
  File "F:\git\myprojecttest\apptest\user.py", line 79, in login
    response_data = {"state": 1, "message": "登录成功","data":{"ceshi":1},"money":money}
UnboundLocalError: local variable 'money' referenced before assignment

=========================
time:2018-02-28 16:16:36,102 
logger:user 
level:ERROR 
file:log.py 
fun:error 
lineno:66 
message:Traceback (most recent call last):
  File "F:\git\myprojecttest\apptest\user.py", line 77, in login
    user[0].objects.update()#保存数据库
  File "F:\git\myprojecttest\venv\lib\site-packages\django\db\models\manager.py", line 178, in __get__
    raise AttributeError("Manager isn't accessible via %s instances" % cls.__name__)
AttributeError: Manager isn't accessible via tmember instances

=========================
time:2018-02-28 16:17:12,197 
logger:user 
level:ERROR 
file:log.py 
fun:error 
lineno:66 
message:Traceback (most recent call last):
  File "F:\git\myprojecttest\apptest\user.py", line 77, in login
    tmember.objects.update(user[0])#保存数据库
  File "F:\git\myprojecttest\venv\lib\site-packages\django\db\models\manager.py", line 82, in manager_method
    return getattr(self.get_queryset(), name)(*args, **kwargs)
TypeError: update() takes 1 positional argument but 2 were given

